[2022-12-29 16:39:30,724] {taskinstance.py:1159} INFO - Dependencies all met for <TaskInstance: load_rates.dag6_load_to_bigquery scheduled__2022-12-28T16:39:12.737691+00:00 [queued]>
[2022-12-29 16:39:30,731] {taskinstance.py:1159} INFO - Dependencies all met for <TaskInstance: load_rates.dag6_load_to_bigquery scheduled__2022-12-28T16:39:12.737691+00:00 [queued]>
[2022-12-29 16:39:30,731] {taskinstance.py:1356} INFO - 
--------------------------------------------------------------------------------
[2022-12-29 16:39:30,731] {taskinstance.py:1357} INFO - Starting attempt 1 of 1
[2022-12-29 16:39:30,731] {taskinstance.py:1358} INFO - 
--------------------------------------------------------------------------------
[2022-12-29 16:39:30,740] {taskinstance.py:1377} INFO - Executing <Task(_PythonDecoratedOperator): dag6_load_to_bigquery> on 2022-12-28 16:39:12.737691+00:00
[2022-12-29 16:39:30,744] {standard_task_runner.py:52} INFO - Started process 15326 to run task
[2022-12-29 16:39:30,747] {standard_task_runner.py:79} INFO - Running: ['***', 'tasks', 'run', 'load_rates', 'dag6_load_to_bigquery', 'scheduled__2022-12-28T16:39:12.737691+00:00', '--job-id', '53', '--raw', '--subdir', 'DAGS_FOLDER/extract_data.py', '--cfg-path', '/tmp/tmp4n_c2tc3', '--error-file', '/tmp/tmphqp5zslp']
[2022-12-29 16:39:30,747] {standard_task_runner.py:80} INFO - Job 53: Subtask dag6_load_to_bigquery
[2022-12-29 16:39:30,784] {task_command.py:369} INFO - Running <TaskInstance: load_rates.dag6_load_to_bigquery scheduled__2022-12-28T16:39:12.737691+00:00 [running]> on host 99c1092660ad
[2022-12-29 16:39:30,838] {taskinstance.py:1571} INFO - Exporting the following env vars:
AIRFLOW_CTX_DAG_OWNER=***
AIRFLOW_CTX_DAG_ID=load_rates
AIRFLOW_CTX_TASK_ID=dag6_load_to_bigquery
AIRFLOW_CTX_EXECUTION_DATE=2022-12-28T16:39:12.737691+00:00
AIRFLOW_CTX_TRY_NUMBER=1
AIRFLOW_CTX_DAG_RUN_ID=scheduled__2022-12-28T16:39:12.737691+00:00
[2022-12-29 16:39:32,684] {taskinstance.py:1889} ERROR - Task failed with exception
Traceback (most recent call last):
  File "/home/airflow/.local/lib/python3.7/site-packages/airflow/decorators/base.py", line 179, in execute
    return_value = super().execute(context)
  File "/home/airflow/.local/lib/python3.7/site-packages/airflow/operators/python.py", line 171, in execute
    return_value = self.execute_callable()
  File "/home/airflow/.local/lib/python3.7/site-packages/airflow/operators/python.py", line 189, in execute_callable
    return self.python_callable(*self.op_args, **self.op_kwargs)
  File "/opt/airflow/dags/extract_data.py", line 69, in dag6_load_to_bigquery
    load_to_bigquery()
  File "/opt/airflow/dags/python/Helper.py", line 196, in load_to_bigquery
    table = bigquery_client.get_table(table_id)
  File "/home/airflow/.local/lib/python3.7/site-packages/google/cloud/bigquery/client.py", line 1040, in get_table
    timeout=timeout,
  File "/home/airflow/.local/lib/python3.7/site-packages/google/cloud/bigquery/client.py", line 782, in _call_api
    return call()
  File "/home/airflow/.local/lib/python3.7/site-packages/google/api_core/retry.py", line 288, in retry_wrapped_func
    on_error=on_error,
  File "/home/airflow/.local/lib/python3.7/site-packages/google/api_core/retry.py", line 190, in retry_target
    return target()
  File "/home/airflow/.local/lib/python3.7/site-packages/google/cloud/_http/__init__.py", line 494, in api_request
    raise exceptions.from_http_response(response)
google.api_core.exceptions.NotFound: 404 GET https://bigquery.googleapis.com/bigquery/v2/projects/bigquery-sandbox-371208/datasets/Forex_Platform/tables/rates?prettyPrint=false: Not found: Table bigquery-sandbox-371208:Forex_Platform.rates
[2022-12-29 16:39:32,690] {taskinstance.py:1400} INFO - Marking task as FAILED. dag_id=load_rates, task_id=dag6_load_to_bigquery, execution_date=20221228T163912, start_date=20221229T163930, end_date=20221229T163932
[2022-12-29 16:39:32,699] {standard_task_runner.py:97} ERROR - Failed to execute job 53 for task dag6_load_to_bigquery (404 GET https://bigquery.googleapis.com/bigquery/v2/projects/bigquery-sandbox-371208/datasets/Forex_Platform/tables/rates?prettyPrint=false: Not found: Table bigquery-sandbox-371208:Forex_Platform.rates; 15326)
[2022-12-29 16:39:32,724] {local_task_job.py:156} INFO - Task exited with return code 1
[2022-12-29 16:39:32,770] {local_task_job.py:273} INFO - 0 downstream tasks scheduled from follow-on schedule check
