[2022-12-30 14:44:07,751] {taskinstance.py:1159} INFO - Dependencies all met for <TaskInstance: insert_new_rates.dag5_load_to_bigquery_EOD manual__2022-12-30T14:44:02.100185+00:00 [queued]>
[2022-12-30 14:44:07,759] {taskinstance.py:1159} INFO - Dependencies all met for <TaskInstance: insert_new_rates.dag5_load_to_bigquery_EOD manual__2022-12-30T14:44:02.100185+00:00 [queued]>
[2022-12-30 14:44:07,759] {taskinstance.py:1356} INFO - 
--------------------------------------------------------------------------------
[2022-12-30 14:44:07,759] {taskinstance.py:1357} INFO - Starting attempt 1 of 1
[2022-12-30 14:44:07,759] {taskinstance.py:1358} INFO - 
--------------------------------------------------------------------------------
[2022-12-30 14:44:07,770] {taskinstance.py:1377} INFO - Executing <Task(_PythonDecoratedOperator): dag5_load_to_bigquery_EOD> on 2022-12-30 14:44:02.100185+00:00
[2022-12-30 14:44:07,775] {standard_task_runner.py:52} INFO - Started process 9847 to run task
[2022-12-30 14:44:07,778] {standard_task_runner.py:79} INFO - Running: ['***', 'tasks', 'run', 'insert_new_rates', 'dag5_load_to_bigquery_EOD', 'manual__2022-12-30T14:44:02.100185+00:00', '--job-id', '120', '--raw', '--subdir', 'DAGS_FOLDER/insert_new_rates.py', '--cfg-path', '/tmp/tmp_75g3wap', '--error-file', '/tmp/tmpdqpo_d5b']
[2022-12-30 14:44:07,779] {standard_task_runner.py:80} INFO - Job 120: Subtask dag5_load_to_bigquery_EOD
[2022-12-30 14:44:07,819] {task_command.py:369} INFO - Running <TaskInstance: insert_new_rates.dag5_load_to_bigquery_EOD manual__2022-12-30T14:44:02.100185+00:00 [running]> on host 99c1092660ad
[2022-12-30 14:44:07,882] {taskinstance.py:1571} INFO - Exporting the following env vars:
AIRFLOW_CTX_DAG_OWNER=***
AIRFLOW_CTX_DAG_ID=insert_new_rates
AIRFLOW_CTX_TASK_ID=dag5_load_to_bigquery_EOD
AIRFLOW_CTX_EXECUTION_DATE=2022-12-30T14:44:02.100185+00:00
AIRFLOW_CTX_TRY_NUMBER=1
AIRFLOW_CTX_DAG_RUN_ID=manual__2022-12-30T14:44:02.100185+00:00
[2022-12-30 14:44:08,079] {taskinstance.py:1889} ERROR - Task failed with exception
Traceback (most recent call last):
  File "/home/airflow/.local/lib/python3.7/site-packages/airflow/decorators/base.py", line 179, in execute
    return_value = super().execute(context)
  File "/home/airflow/.local/lib/python3.7/site-packages/airflow/operators/python.py", line 171, in execute
    return_value = self.execute_callable()
  File "/home/airflow/.local/lib/python3.7/site-packages/airflow/operators/python.py", line 189, in execute_callable
    return self.python_callable(*self.op_args, **self.op_kwargs)
  File "/opt/airflow/dags/insert_new_rates.py", line 74, in dag5_load_to_bigquery_EOD
    load_to_bigquery_EOD(new_df = new_df)
  File "/opt/airflow/dags/python/Helper.py", line 294, in load_to_bigquery_EOD
    bigquery_client = bigquery.Client()
  File "/home/airflow/.local/lib/python3.7/site-packages/google/cloud/bigquery/client.py", line 235, in __init__
    _http=_http,
  File "/home/airflow/.local/lib/python3.7/site-packages/google/cloud/client/__init__.py", line 320, in __init__
    _ClientProjectMixin.__init__(self, project=project, credentials=credentials)
  File "/home/airflow/.local/lib/python3.7/site-packages/google/cloud/client/__init__.py", line 268, in __init__
    project = self._determine_default(project)
  File "/home/airflow/.local/lib/python3.7/site-packages/google/cloud/client/__init__.py", line 287, in _determine_default
    return _determine_default_project(project)
  File "/home/airflow/.local/lib/python3.7/site-packages/google/cloud/_helpers/__init__.py", line 152, in _determine_default_project
    _, project = google.auth.default()
  File "/home/airflow/.local/lib/python3.7/site-packages/google/auth/_default.py", line 546, in default
    credentials, project_id = checker()
  File "/home/airflow/.local/lib/python3.7/site-packages/google/auth/_default.py", line 539, in <lambda>
    lambda: _get_explicit_environ_credentials(quota_project_id=quota_project_id),
  File "/home/airflow/.local/lib/python3.7/site-packages/google/auth/_default.py", line 219, in _get_explicit_environ_credentials
    os.environ[environment_vars.CREDENTIALS], quota_project_id=quota_project_id
  File "/home/airflow/.local/lib/python3.7/site-packages/google/auth/_default.py", line 118, in load_credentials_from_file
    "File {} was not found.".format(filename)
google.auth.exceptions.DefaultCredentialsError: File ServiceKey_GoogleCloud.json was not found.
[2022-12-30 14:44:08,085] {taskinstance.py:1400} INFO - Marking task as FAILED. dag_id=insert_new_rates, task_id=dag5_load_to_bigquery_EOD, execution_date=20221230T144402, start_date=20221230T144407, end_date=20221230T144408
[2022-12-30 14:44:08,094] {standard_task_runner.py:97} ERROR - Failed to execute job 120 for task dag5_load_to_bigquery_EOD (File ServiceKey_GoogleCloud.json was not found.; 9847)
[2022-12-30 14:44:08,111] {local_task_job.py:156} INFO - Task exited with return code 1
[2022-12-30 14:44:08,132] {local_task_job.py:273} INFO - 0 downstream tasks scheduled from follow-on schedule check
