[2022-12-12 13:06:09,873] {taskinstance.py:1159} INFO - Dependencies all met for <TaskInstance: load_rates.create_dataframe manual__2022-12-12T13:06:07.692750+00:00 [queued]>
[2022-12-12 13:06:09,878] {taskinstance.py:1159} INFO - Dependencies all met for <TaskInstance: load_rates.create_dataframe manual__2022-12-12T13:06:07.692750+00:00 [queued]>
[2022-12-12 13:06:09,878] {taskinstance.py:1356} INFO - 
--------------------------------------------------------------------------------
[2022-12-12 13:06:09,878] {taskinstance.py:1357} INFO - Starting attempt 1 of 1
[2022-12-12 13:06:09,878] {taskinstance.py:1358} INFO - 
--------------------------------------------------------------------------------
[2022-12-12 13:06:09,888] {taskinstance.py:1377} INFO - Executing <Task(_PythonDecoratedOperator): create_dataframe> on 2022-12-12 13:06:07.692750+00:00
[2022-12-12 13:06:09,893] {standard_task_runner.py:52} INFO - Started process 4294 to run task
[2022-12-12 13:06:09,896] {standard_task_runner.py:79} INFO - Running: ['***', 'tasks', 'run', 'load_rates', 'create_dataframe', 'manual__2022-12-12T13:06:07.692750+00:00', '--job-id', '27', '--raw', '--subdir', 'DAGS_FOLDER/load_rates.py', '--cfg-path', '/tmp/tmpzquc6api', '--error-file', '/tmp/tmpxkek9pcq']
[2022-12-12 13:06:09,896] {standard_task_runner.py:80} INFO - Job 27: Subtask create_dataframe
[2022-12-12 13:06:09,934] {task_command.py:369} INFO - Running <TaskInstance: load_rates.create_dataframe manual__2022-12-12T13:06:07.692750+00:00 [running]> on host 58259600a754
[2022-12-12 13:06:10,015] {taskinstance.py:1571} INFO - Exporting the following env vars:
AIRFLOW_CTX_DAG_OWNER=***
AIRFLOW_CTX_DAG_ID=load_rates
AIRFLOW_CTX_TASK_ID=create_dataframe
AIRFLOW_CTX_EXECUTION_DATE=2022-12-12T13:06:07.692750+00:00
AIRFLOW_CTX_TRY_NUMBER=1
AIRFLOW_CTX_DAG_RUN_ID=manual__2022-12-12T13:06:07.692750+00:00
[2022-12-12 13:06:10,030] {taskinstance.py:1889} ERROR - Task failed with exception
Traceback (most recent call last):
  File "/home/airflow/.local/lib/python3.7/site-packages/airflow/decorators/base.py", line 179, in execute
    return_value = super().execute(context)
  File "/home/airflow/.local/lib/python3.7/site-packages/airflow/operators/python.py", line 171, in execute
    return_value = self.execute_callable()
  File "/home/airflow/.local/lib/python3.7/site-packages/airflow/operators/python.py", line 189, in execute_callable
    return self.python_callable(*self.op_args, **self.op_kwargs)
  File "/opt/airflow/dags/load_rates.py", line 95, in create_dataframe
    first_day_df.to_csv('dags/python/rates.csv')
  File "/home/airflow/.local/lib/python3.7/site-packages/pandas/core/generic.py", line 3482, in to_csv
    storage_options=storage_options,
  File "/home/airflow/.local/lib/python3.7/site-packages/pandas/io/formats/format.py", line 1105, in to_csv
    csv_formatter.save()
  File "/home/airflow/.local/lib/python3.7/site-packages/pandas/io/formats/csvs.py", line 243, in save
    storage_options=self.storage_options,
  File "/home/airflow/.local/lib/python3.7/site-packages/pandas/io/common.py", line 707, in get_handle
    newline="",
PermissionError: [Errno 13] Permission denied: 'dags/python/rates.csv'
[2022-12-12 13:06:10,040] {taskinstance.py:1400} INFO - Marking task as FAILED. dag_id=load_rates, task_id=create_dataframe, execution_date=20221212T130607, start_date=20221212T130609, end_date=20221212T130610
[2022-12-12 13:06:10,047] {standard_task_runner.py:97} ERROR - Failed to execute job 27 for task create_dataframe ([Errno 13] Permission denied: 'dags/python/rates.csv'; 4294)
[2022-12-12 13:06:10,068] {local_task_job.py:156} INFO - Task exited with return code 1
[2022-12-12 13:06:10,089] {local_task_job.py:273} INFO - 0 downstream tasks scheduled from follow-on schedule check
