[2022-12-14 09:46:41,434] {taskinstance.py:1159} INFO - Dependencies all met for <TaskInstance: load_rates.load_to_google_storage manual__2022-12-14T09:46:36.536031+00:00 [queued]>
[2022-12-14 09:46:41,441] {taskinstance.py:1159} INFO - Dependencies all met for <TaskInstance: load_rates.load_to_google_storage manual__2022-12-14T09:46:36.536031+00:00 [queued]>
[2022-12-14 09:46:41,441] {taskinstance.py:1356} INFO - 
--------------------------------------------------------------------------------
[2022-12-14 09:46:41,441] {taskinstance.py:1357} INFO - Starting attempt 1 of 1
[2022-12-14 09:46:41,441] {taskinstance.py:1358} INFO - 
--------------------------------------------------------------------------------
[2022-12-14 09:46:41,450] {taskinstance.py:1377} INFO - Executing <Task(_PythonDecoratedOperator): load_to_google_storage> on 2022-12-14 09:46:36.536031+00:00
[2022-12-14 09:46:41,454] {standard_task_runner.py:52} INFO - Started process 452 to run task
[2022-12-14 09:46:41,456] {standard_task_runner.py:79} INFO - Running: ['***', 'tasks', 'run', 'load_rates', 'load_to_google_storage', 'manual__2022-12-14T09:46:36.536031+00:00', '--job-id', '74', '--raw', '--subdir', 'DAGS_FOLDER/extract_data.py', '--cfg-path', '/tmp/tmph0sqbt07', '--error-file', '/tmp/tmp3zbpq703']
[2022-12-14 09:46:41,457] {standard_task_runner.py:80} INFO - Job 74: Subtask load_to_google_storage
[2022-12-14 09:46:41,490] {task_command.py:369} INFO - Running <TaskInstance: load_rates.load_to_google_storage manual__2022-12-14T09:46:36.536031+00:00 [running]> on host a25e5c0223cd
[2022-12-14 09:46:41,543] {taskinstance.py:1571} INFO - Exporting the following env vars:
AIRFLOW_CTX_DAG_OWNER=***
AIRFLOW_CTX_DAG_ID=load_rates
AIRFLOW_CTX_TASK_ID=load_to_google_storage
AIRFLOW_CTX_EXECUTION_DATE=2022-12-14T09:46:36.536031+00:00
AIRFLOW_CTX_TRY_NUMBER=1
AIRFLOW_CTX_DAG_RUN_ID=manual__2022-12-14T09:46:36.536031+00:00
[2022-12-14 09:46:42,213] {taskinstance.py:1889} ERROR - Task failed with exception
Traceback (most recent call last):
  File "/home/airflow/.local/lib/python3.7/site-packages/airflow/decorators/base.py", line 179, in execute
    return_value = super().execute(context)
  File "/home/airflow/.local/lib/python3.7/site-packages/airflow/operators/python.py", line 171, in execute
    return_value = self.execute_callable()
  File "/home/airflow/.local/lib/python3.7/site-packages/airflow/operators/python.py", line 189, in execute_callable
    return self.python_callable(*self.op_args, **self.op_kwargs)
  File "/opt/airflow/dags/extract_data.py", line 103, in load_to_google_storage
    blob.upload_from_filename('rates.csv')
  File "/home/airflow/.local/lib/python3.7/site-packages/google/cloud/storage/blob.py", line 2720, in upload_from_filename
    with open(filename, "rb") as file_obj:
FileNotFoundError: [Errno 2] No such file or directory: 'rates.csv'
[2022-12-14 09:46:42,220] {taskinstance.py:1400} INFO - Marking task as FAILED. dag_id=load_rates, task_id=load_to_google_storage, execution_date=20221214T094636, start_date=20221214T094641, end_date=20221214T094642
[2022-12-14 09:46:42,229] {standard_task_runner.py:97} ERROR - Failed to execute job 74 for task load_to_google_storage ([Errno 2] No such file or directory: 'rates.csv'; 452)
[2022-12-14 09:46:42,270] {local_task_job.py:156} INFO - Task exited with return code 1
[2022-12-14 09:46:42,291] {local_task_job.py:273} INFO - 0 downstream tasks scheduled from follow-on schedule check
