[2022-12-30 12:47:03,098] {taskinstance.py:1159} INFO - Dependencies all met for <TaskInstance: insert_new_rates.dag1_grab_next_date manual__2022-12-30T12:47:02.504096+00:00 [queued]>
[2022-12-30 12:47:03,104] {taskinstance.py:1159} INFO - Dependencies all met for <TaskInstance: insert_new_rates.dag1_grab_next_date manual__2022-12-30T12:47:02.504096+00:00 [queued]>
[2022-12-30 12:47:03,104] {taskinstance.py:1356} INFO - 
--------------------------------------------------------------------------------
[2022-12-30 12:47:03,104] {taskinstance.py:1357} INFO - Starting attempt 1 of 1
[2022-12-30 12:47:03,104] {taskinstance.py:1358} INFO - 
--------------------------------------------------------------------------------
[2022-12-30 12:47:03,114] {taskinstance.py:1377} INFO - Executing <Task(_PythonDecoratedOperator): dag1_grab_next_date> on 2022-12-30 12:47:02.504096+00:00
[2022-12-30 12:47:03,118] {standard_task_runner.py:52} INFO - Started process 3759 to run task
[2022-12-30 12:47:03,120] {standard_task_runner.py:79} INFO - Running: ['***', 'tasks', 'run', 'insert_new_rates', 'dag1_grab_next_date', 'manual__2022-12-30T12:47:02.504096+00:00', '--job-id', '69', '--raw', '--subdir', 'DAGS_FOLDER/insert_new_rates.py', '--cfg-path', '/tmp/tmpqys7gazm', '--error-file', '/tmp/tmp9tgnmr7l']
[2022-12-30 12:47:03,121] {standard_task_runner.py:80} INFO - Job 69: Subtask dag1_grab_next_date
[2022-12-30 12:47:03,159] {task_command.py:369} INFO - Running <TaskInstance: insert_new_rates.dag1_grab_next_date manual__2022-12-30T12:47:02.504096+00:00 [running]> on host 99c1092660ad
[2022-12-30 12:47:03,210] {taskinstance.py:1571} INFO - Exporting the following env vars:
AIRFLOW_CTX_DAG_OWNER=***
AIRFLOW_CTX_DAG_ID=insert_new_rates
AIRFLOW_CTX_TASK_ID=dag1_grab_next_date
AIRFLOW_CTX_EXECUTION_DATE=2022-12-30T12:47:02.504096+00:00
AIRFLOW_CTX_TRY_NUMBER=1
AIRFLOW_CTX_DAG_RUN_ID=manual__2022-12-30T12:47:02.504096+00:00
[2022-12-30 12:47:03,211] {taskinstance.py:1889} ERROR - Task failed with exception
Traceback (most recent call last):
  File "/home/airflow/.local/lib/python3.7/site-packages/airflow/decorators/base.py", line 179, in execute
    return_value = super().execute(context)
  File "/home/airflow/.local/lib/python3.7/site-packages/airflow/operators/python.py", line 171, in execute
    return_value = self.execute_callable()
  File "/home/airflow/.local/lib/python3.7/site-packages/airflow/operators/python.py", line 189, in execute_callable
    return self.python_callable(*self.op_args, **self.op_kwargs)
  File "/opt/airflow/dags/insert_new_rates.py", line 36, in dag1_grab_next_date
    next_date = grab_next_date()
  File "/opt/airflow/dags/python/Helper.py", line 218, in grab_next_date
    start_date_datetime = datetime.datetime.fromisoformat(latest_day)
AttributeError: type object 'datetime.datetime' has no attribute 'datetime'
[2022-12-30 12:47:03,218] {taskinstance.py:1400} INFO - Marking task as FAILED. dag_id=insert_new_rates, task_id=dag1_grab_next_date, execution_date=20221230T124702, start_date=20221230T124703, end_date=20221230T124703
[2022-12-30 12:47:03,226] {standard_task_runner.py:97} ERROR - Failed to execute job 69 for task dag1_grab_next_date (type object 'datetime.datetime' has no attribute 'datetime'; 3759)
[2022-12-30 12:47:03,252] {local_task_job.py:156} INFO - Task exited with return code 1
[2022-12-30 12:47:03,283] {local_task_job.py:273} INFO - 0 downstream tasks scheduled from follow-on schedule check
