[2022-12-30 14:19:07,399] {taskinstance.py:1159} INFO - Dependencies all met for <TaskInstance: insert_new_rates.dag5_load_to_bigquery_EOD manual__2022-12-30T14:19:02.069386+00:00 [queued]>
[2022-12-30 14:19:07,405] {taskinstance.py:1159} INFO - Dependencies all met for <TaskInstance: insert_new_rates.dag5_load_to_bigquery_EOD manual__2022-12-30T14:19:02.069386+00:00 [queued]>
[2022-12-30 14:19:07,405] {taskinstance.py:1356} INFO - 
--------------------------------------------------------------------------------
[2022-12-30 14:19:07,405] {taskinstance.py:1357} INFO - Starting attempt 1 of 1
[2022-12-30 14:19:07,406] {taskinstance.py:1358} INFO - 
--------------------------------------------------------------------------------
[2022-12-30 14:19:07,416] {taskinstance.py:1377} INFO - Executing <Task(_PythonDecoratedOperator): dag5_load_to_bigquery_EOD> on 2022-12-30 14:19:02.069386+00:00
[2022-12-30 14:19:07,421] {standard_task_runner.py:52} INFO - Started process 8489 to run task
[2022-12-30 14:19:07,423] {standard_task_runner.py:79} INFO - Running: ['***', 'tasks', 'run', 'insert_new_rates', 'dag5_load_to_bigquery_EOD', 'manual__2022-12-30T14:19:02.069386+00:00', '--job-id', '89', '--raw', '--subdir', 'DAGS_FOLDER/insert_new_rates.py', '--cfg-path', '/tmp/tmpn1_ysv5c', '--error-file', '/tmp/tmpfo8eg5_b']
[2022-12-30 14:19:07,424] {standard_task_runner.py:80} INFO - Job 89: Subtask dag5_load_to_bigquery_EOD
[2022-12-30 14:19:07,462] {task_command.py:369} INFO - Running <TaskInstance: insert_new_rates.dag5_load_to_bigquery_EOD manual__2022-12-30T14:19:02.069386+00:00 [running]> on host 99c1092660ad
[2022-12-30 14:19:07,517] {taskinstance.py:1571} INFO - Exporting the following env vars:
AIRFLOW_CTX_DAG_OWNER=***
AIRFLOW_CTX_DAG_ID=insert_new_rates
AIRFLOW_CTX_TASK_ID=dag5_load_to_bigquery_EOD
AIRFLOW_CTX_EXECUTION_DATE=2022-12-30T14:19:02.069386+00:00
AIRFLOW_CTX_TRY_NUMBER=1
AIRFLOW_CTX_DAG_RUN_ID=manual__2022-12-30T14:19:02.069386+00:00
[2022-12-30 14:19:07,695] {taskinstance.py:1889} ERROR - Task failed with exception
Traceback (most recent call last):
  File "/home/airflow/.local/lib/python3.7/site-packages/airflow/decorators/base.py", line 179, in execute
    return_value = super().execute(context)
  File "/home/airflow/.local/lib/python3.7/site-packages/airflow/operators/python.py", line 171, in execute
    return_value = self.execute_callable()
  File "/home/airflow/.local/lib/python3.7/site-packages/airflow/operators/python.py", line 189, in execute_callable
    return self.python_callable(*self.op_args, **self.op_kwargs)
  File "/opt/airflow/dags/insert_new_rates.py", line 70, in dag5_load_to_bigquery_EOD
    load_to_bigquery_EOD(start_date=next_date)
  File "/opt/airflow/dags/python/Helper.py", line 298, in load_to_bigquery_EOD
    rates = pd.read_csv(f'processed_rates_{start_date}.csv', index_col='Unnamed: 0')
  File "/home/airflow/.local/lib/python3.7/site-packages/pandas/util/_decorators.py", line 311, in wrapper
    return func(*args, **kwargs)
  File "/home/airflow/.local/lib/python3.7/site-packages/pandas/io/parsers/readers.py", line 586, in read_csv
    return _read(filepath_or_buffer, kwds)
  File "/home/airflow/.local/lib/python3.7/site-packages/pandas/io/parsers/readers.py", line 482, in _read
    parser = TextFileReader(filepath_or_buffer, **kwds)
  File "/home/airflow/.local/lib/python3.7/site-packages/pandas/io/parsers/readers.py", line 811, in __init__
    self._engine = self._make_engine(self.engine)
  File "/home/airflow/.local/lib/python3.7/site-packages/pandas/io/parsers/readers.py", line 1040, in _make_engine
    return mapping[engine](self.f, **self.options)  # type: ignore[call-arg]
  File "/home/airflow/.local/lib/python3.7/site-packages/pandas/io/parsers/c_parser_wrapper.py", line 51, in __init__
    self._open_handles(src, kwds)
  File "/home/airflow/.local/lib/python3.7/site-packages/pandas/io/parsers/base_parser.py", line 229, in _open_handles
    errors=kwds.get("encoding_errors", "strict"),
  File "/home/airflow/.local/lib/python3.7/site-packages/pandas/io/common.py", line 707, in get_handle
    newline="",
FileNotFoundError: [Errno 2] No such file or directory: 'processed_rates_2022-03-05.csv'
[2022-12-30 14:19:07,703] {taskinstance.py:1400} INFO - Marking task as FAILED. dag_id=insert_new_rates, task_id=dag5_load_to_bigquery_EOD, execution_date=20221230T141902, start_date=20221230T141907, end_date=20221230T141907
[2022-12-30 14:19:07,710] {standard_task_runner.py:97} ERROR - Failed to execute job 89 for task dag5_load_to_bigquery_EOD ([Errno 2] No such file or directory: 'processed_rates_2022-03-05.csv'; 8489)
[2022-12-30 14:19:07,755] {local_task_job.py:156} INFO - Task exited with return code 1
[2022-12-30 14:19:07,776] {local_task_job.py:273} INFO - 0 downstream tasks scheduled from follow-on schedule check
