[2022-12-12 16:22:52,604] {taskinstance.py:1159} INFO - Dependencies all met for <TaskInstance: load_rates.load_to_google_storage manual__2022-12-12T16:22:49.892986+00:00 [queued]>
[2022-12-12 16:22:52,611] {taskinstance.py:1159} INFO - Dependencies all met for <TaskInstance: load_rates.load_to_google_storage manual__2022-12-12T16:22:49.892986+00:00 [queued]>
[2022-12-12 16:22:52,611] {taskinstance.py:1356} INFO - 
--------------------------------------------------------------------------------
[2022-12-12 16:22:52,611] {taskinstance.py:1357} INFO - Starting attempt 1 of 1
[2022-12-12 16:22:52,611] {taskinstance.py:1358} INFO - 
--------------------------------------------------------------------------------
[2022-12-12 16:22:52,621] {taskinstance.py:1377} INFO - Executing <Task(_PythonDecoratedOperator): load_to_google_storage> on 2022-12-12 16:22:49.892986+00:00
[2022-12-12 16:22:52,627] {standard_task_runner.py:52} INFO - Started process 11105 to run task
[2022-12-12 16:22:52,630] {standard_task_runner.py:79} INFO - Running: ['***', 'tasks', 'run', 'load_rates', 'load_to_google_storage', 'manual__2022-12-12T16:22:49.892986+00:00', '--job-id', '58', '--raw', '--subdir', 'DAGS_FOLDER/extract_data.py', '--cfg-path', '/tmp/tmprcx7ldtt', '--error-file', '/tmp/tmp9a1tc6vk']
[2022-12-12 16:22:52,630] {standard_task_runner.py:80} INFO - Job 58: Subtask load_to_google_storage
[2022-12-12 16:22:52,674] {task_command.py:369} INFO - Running <TaskInstance: load_rates.load_to_google_storage manual__2022-12-12T16:22:49.892986+00:00 [running]> on host 58259600a754
[2022-12-12 16:22:52,732] {taskinstance.py:1571} INFO - Exporting the following env vars:
AIRFLOW_CTX_DAG_OWNER=***
AIRFLOW_CTX_DAG_ID=load_rates
AIRFLOW_CTX_TASK_ID=load_to_google_storage
AIRFLOW_CTX_EXECUTION_DATE=2022-12-12T16:22:49.892986+00:00
AIRFLOW_CTX_TRY_NUMBER=1
AIRFLOW_CTX_DAG_RUN_ID=manual__2022-12-12T16:22:49.892986+00:00
[2022-12-12 16:22:53,899] {taskinstance.py:1889} ERROR - Task failed with exception
Traceback (most recent call last):
  File "/home/airflow/.local/lib/python3.7/site-packages/airflow/decorators/base.py", line 179, in execute
    return_value = super().execute(context)
  File "/home/airflow/.local/lib/python3.7/site-packages/airflow/operators/python.py", line 171, in execute
    return_value = self.execute_callable()
  File "/home/airflow/.local/lib/python3.7/site-packages/airflow/operators/python.py", line 189, in execute_callable
    return self.python_callable(*self.op_args, **self.op_kwargs)
  File "/opt/airflow/dags/extract_data.py", line 113, in load_to_google_storage
    bucket = storage_client.get_bucket(bucket_or_name='forex_investing_platform')
  File "/home/airflow/.local/lib/python3.7/site-packages/google/cloud/storage/client.py", line 770, in get_bucket
    retry=retry,
  File "/home/airflow/.local/lib/python3.7/site-packages/google/cloud/storage/bucket.py", line 1016, in reload
    retry=retry,
  File "/home/airflow/.local/lib/python3.7/site-packages/google/cloud/storage/_helpers.py", line 233, in reload
    _target_object=self,
  File "/home/airflow/.local/lib/python3.7/site-packages/google/cloud/storage/client.py", line 356, in _get_resource
    _target_object=_target_object,
  File "/home/airflow/.local/lib/python3.7/site-packages/google/cloud/storage/_http.py", line 80, in api_request
    return call()
  File "/home/airflow/.local/lib/python3.7/site-packages/google/api_core/retry.py", line 288, in retry_wrapped_func
    on_error=on_error,
  File "/home/airflow/.local/lib/python3.7/site-packages/google/api_core/retry.py", line 190, in retry_target
    return target()
  File "/home/airflow/.local/lib/python3.7/site-packages/google/cloud/_http/__init__.py", line 494, in api_request
    raise exceptions.from_http_response(response)
google.api_core.exceptions.NotFound: 404 GET https://storage.googleapis.com/storage/v1/b/forex_investing_platform?projection=noAcl&prettyPrint=false: The specified bucket does not exist.
[2022-12-12 16:22:53,909] {taskinstance.py:1400} INFO - Marking task as FAILED. dag_id=load_rates, task_id=load_to_google_storage, execution_date=20221212T162249, start_date=20221212T162252, end_date=20221212T162253
[2022-12-12 16:22:53,918] {standard_task_runner.py:97} ERROR - Failed to execute job 58 for task load_to_google_storage (404 GET https://storage.googleapis.com/storage/v1/b/forex_investing_platform?projection=noAcl&prettyPrint=false: The specified bucket does not exist.; 11105)
[2022-12-12 16:22:53,966] {local_task_job.py:156} INFO - Task exited with return code 1
[2022-12-12 16:22:54,023] {local_task_job.py:273} INFO - 0 downstream tasks scheduled from follow-on schedule check
