[2022-12-30 14:30:50,449] {taskinstance.py:1159} INFO - Dependencies all met for <TaskInstance: insert_new_rates.dag5_load_to_bigquery_EOD manual__2022-12-30T14:30:44.197206+00:00 [queued]>
[2022-12-30 14:30:50,455] {taskinstance.py:1159} INFO - Dependencies all met for <TaskInstance: insert_new_rates.dag5_load_to_bigquery_EOD manual__2022-12-30T14:30:44.197206+00:00 [queued]>
[2022-12-30 14:30:50,455] {taskinstance.py:1356} INFO - 
--------------------------------------------------------------------------------
[2022-12-30 14:30:50,455] {taskinstance.py:1357} INFO - Starting attempt 1 of 1
[2022-12-30 14:30:50,455] {taskinstance.py:1358} INFO - 
--------------------------------------------------------------------------------
[2022-12-30 14:30:50,464] {taskinstance.py:1377} INFO - Executing <Task(_PythonDecoratedOperator): dag5_load_to_bigquery_EOD> on 2022-12-30 14:30:44.197206+00:00
[2022-12-30 14:30:50,468] {standard_task_runner.py:52} INFO - Started process 9130 to run task
[2022-12-30 14:30:50,471] {standard_task_runner.py:79} INFO - Running: ['***', 'tasks', 'run', 'insert_new_rates', 'dag5_load_to_bigquery_EOD', 'manual__2022-12-30T14:30:44.197206+00:00', '--job-id', '105', '--raw', '--subdir', 'DAGS_FOLDER/insert_new_rates.py', '--cfg-path', '/tmp/tmpjzc06y4e', '--error-file', '/tmp/tmpw7e7byrz']
[2022-12-30 14:30:50,471] {standard_task_runner.py:80} INFO - Job 105: Subtask dag5_load_to_bigquery_EOD
[2022-12-30 14:30:50,506] {task_command.py:369} INFO - Running <TaskInstance: insert_new_rates.dag5_load_to_bigquery_EOD manual__2022-12-30T14:30:44.197206+00:00 [running]> on host 99c1092660ad
[2022-12-30 14:30:50,559] {taskinstance.py:1571} INFO - Exporting the following env vars:
AIRFLOW_CTX_DAG_OWNER=***
AIRFLOW_CTX_DAG_ID=insert_new_rates
AIRFLOW_CTX_TASK_ID=dag5_load_to_bigquery_EOD
AIRFLOW_CTX_EXECUTION_DATE=2022-12-30T14:30:44.197206+00:00
AIRFLOW_CTX_TRY_NUMBER=1
AIRFLOW_CTX_DAG_RUN_ID=manual__2022-12-30T14:30:44.197206+00:00
[2022-12-30 14:30:50,746] {logging_mixin.py:115} INFO - 2022-03-05
[2022-12-30 14:30:50,750] {taskinstance.py:1889} ERROR - Task failed with exception
Traceback (most recent call last):
  File "/home/airflow/.local/lib/python3.7/site-packages/airflow/decorators/base.py", line 179, in execute
    return_value = super().execute(context)
  File "/home/airflow/.local/lib/python3.7/site-packages/airflow/operators/python.py", line 171, in execute
    return_value = self.execute_callable()
  File "/home/airflow/.local/lib/python3.7/site-packages/airflow/operators/python.py", line 189, in execute_callable
    return self.python_callable(*self.op_args, **self.op_kwargs)
  File "/opt/airflow/dags/insert_new_rates.py", line 68, in dag5_load_to_bigquery_EOD
    load_to_bigquery_EOD(start_date=next_date)
  File "/opt/airflow/dags/python/Helper.py", line 301, in load_to_bigquery_EOD
    bigquery_client = bigquery.Client()
  File "/home/airflow/.local/lib/python3.7/site-packages/google/cloud/bigquery/client.py", line 235, in __init__
    _http=_http,
  File "/home/airflow/.local/lib/python3.7/site-packages/google/cloud/client/__init__.py", line 320, in __init__
    _ClientProjectMixin.__init__(self, project=project, credentials=credentials)
  File "/home/airflow/.local/lib/python3.7/site-packages/google/cloud/client/__init__.py", line 268, in __init__
    project = self._determine_default(project)
  File "/home/airflow/.local/lib/python3.7/site-packages/google/cloud/client/__init__.py", line 287, in _determine_default
    return _determine_default_project(project)
  File "/home/airflow/.local/lib/python3.7/site-packages/google/cloud/_helpers/__init__.py", line 152, in _determine_default_project
    _, project = google.auth.default()
  File "/home/airflow/.local/lib/python3.7/site-packages/google/auth/_default.py", line 546, in default
    credentials, project_id = checker()
  File "/home/airflow/.local/lib/python3.7/site-packages/google/auth/_default.py", line 539, in <lambda>
    lambda: _get_explicit_environ_credentials(quota_project_id=quota_project_id),
  File "/home/airflow/.local/lib/python3.7/site-packages/google/auth/_default.py", line 219, in _get_explicit_environ_credentials
    os.environ[environment_vars.CREDENTIALS], quota_project_id=quota_project_id
  File "/home/airflow/.local/lib/python3.7/site-packages/google/auth/_default.py", line 118, in load_credentials_from_file
    "File {} was not found.".format(filename)
google.auth.exceptions.DefaultCredentialsError: File dags/ServiceKey_GoogleCloud.json was not found.
[2022-12-30 14:30:50,772] {taskinstance.py:1400} INFO - Marking task as FAILED. dag_id=insert_new_rates, task_id=dag5_load_to_bigquery_EOD, execution_date=20221230T143044, start_date=20221230T143050, end_date=20221230T143050
[2022-12-30 14:30:50,782] {standard_task_runner.py:97} ERROR - Failed to execute job 105 for task dag5_load_to_bigquery_EOD (File dags/ServiceKey_GoogleCloud.json was not found.; 9130)
[2022-12-30 14:30:50,803] {local_task_job.py:156} INFO - Task exited with return code 1
[2022-12-30 14:30:50,826] {local_task_job.py:273} INFO - 0 downstream tasks scheduled from follow-on schedule check
