[2022-12-30 12:36:41,829] {taskinstance.py:1159} INFO - Dependencies all met for <TaskInstance: insert_new_rates.dag3_extract_rates_dictionary manual__2022-12-30T12:36:38.431304+00:00 [queued]>
[2022-12-30 12:36:41,835] {taskinstance.py:1159} INFO - Dependencies all met for <TaskInstance: insert_new_rates.dag3_extract_rates_dictionary manual__2022-12-30T12:36:38.431304+00:00 [queued]>
[2022-12-30 12:36:41,835] {taskinstance.py:1356} INFO - 
--------------------------------------------------------------------------------
[2022-12-30 12:36:41,835] {taskinstance.py:1357} INFO - Starting attempt 1 of 1
[2022-12-30 12:36:41,835] {taskinstance.py:1358} INFO - 
--------------------------------------------------------------------------------
[2022-12-30 12:36:41,844] {taskinstance.py:1377} INFO - Executing <Task(_PythonDecoratedOperator): dag3_extract_rates_dictionary> on 2022-12-30 12:36:38.431304+00:00
[2022-12-30 12:36:41,849] {standard_task_runner.py:52} INFO - Started process 3233 to run task
[2022-12-30 12:36:41,852] {standard_task_runner.py:79} INFO - Running: ['***', 'tasks', 'run', 'insert_new_rates', 'dag3_extract_rates_dictionary', 'manual__2022-12-30T12:36:38.431304+00:00', '--job-id', '68', '--raw', '--subdir', 'DAGS_FOLDER/insert_new_rates.py', '--cfg-path', '/tmp/tmplifh26a3', '--error-file', '/tmp/tmpo575aw8a']
[2022-12-30 12:36:41,852] {standard_task_runner.py:80} INFO - Job 68: Subtask dag3_extract_rates_dictionary
[2022-12-30 12:36:41,892] {task_command.py:369} INFO - Running <TaskInstance: insert_new_rates.dag3_extract_rates_dictionary manual__2022-12-30T12:36:38.431304+00:00 [running]> on host 99c1092660ad
[2022-12-30 12:36:41,950] {taskinstance.py:1571} INFO - Exporting the following env vars:
AIRFLOW_CTX_DAG_OWNER=***
AIRFLOW_CTX_DAG_ID=insert_new_rates
AIRFLOW_CTX_TASK_ID=dag3_extract_rates_dictionary
AIRFLOW_CTX_EXECUTION_DATE=2022-12-30T12:36:38.431304+00:00
AIRFLOW_CTX_TRY_NUMBER=1
AIRFLOW_CTX_DAG_RUN_ID=manual__2022-12-30T12:36:38.431304+00:00
[2022-12-30 12:36:41,951] {taskinstance.py:1889} ERROR - Task failed with exception
Traceback (most recent call last):
  File "/home/airflow/.local/lib/python3.7/site-packages/airflow/decorators/base.py", line 179, in execute
    return_value = super().execute(context)
  File "/home/airflow/.local/lib/python3.7/site-packages/airflow/operators/python.py", line 171, in execute
    return_value = self.execute_callable()
  File "/home/airflow/.local/lib/python3.7/site-packages/airflow/operators/python.py", line 189, in execute_callable
    return self.python_callable(*self.op_args, **self.op_kwargs)
  File "/opt/airflow/dags/insert_new_rates.py", line 58, in dag3_extract_rates_dictionary
    rates = extract_rates_dictionary(results)
  File "/opt/airflow/dags/python/Helper.py", line 59, in extract_rates_dictionary
    rates = data['rates']
KeyError: 'rates'
[2022-12-30 12:36:41,957] {taskinstance.py:1400} INFO - Marking task as FAILED. dag_id=insert_new_rates, task_id=dag3_extract_rates_dictionary, execution_date=20221230T123638, start_date=20221230T123641, end_date=20221230T123641
[2022-12-30 12:36:41,966] {standard_task_runner.py:97} ERROR - Failed to execute job 68 for task dag3_extract_rates_dictionary ('rates'; 3233)
[2022-12-30 12:36:41,984] {local_task_job.py:156} INFO - Task exited with return code 1
[2022-12-30 12:36:42,014] {local_task_job.py:273} INFO - 0 downstream tasks scheduled from follow-on schedule check
