[2022-12-30 14:13:21,106] {taskinstance.py:1159} INFO - Dependencies all met for <TaskInstance: insert_new_rates.dag4_process_EOD_rates manual__2022-12-30T14:01:30.148908+00:00 [queued]>
[2022-12-30 14:13:21,115] {taskinstance.py:1159} INFO - Dependencies all met for <TaskInstance: insert_new_rates.dag4_process_EOD_rates manual__2022-12-30T14:01:30.148908+00:00 [queued]>
[2022-12-30 14:13:21,116] {taskinstance.py:1356} INFO - 
--------------------------------------------------------------------------------
[2022-12-30 14:13:21,116] {taskinstance.py:1357} INFO - Starting attempt 3 of 3
[2022-12-30 14:13:21,116] {taskinstance.py:1358} INFO - 
--------------------------------------------------------------------------------
[2022-12-30 14:13:21,128] {taskinstance.py:1377} INFO - Executing <Task(_PythonDecoratedOperator): dag4_process_EOD_rates> on 2022-12-30 14:01:30.148908+00:00
[2022-12-30 14:13:21,132] {standard_task_runner.py:52} INFO - Started process 8156 to run task
[2022-12-30 14:13:21,135] {standard_task_runner.py:79} INFO - Running: ['***', 'tasks', 'run', 'insert_new_rates', 'dag4_process_EOD_rates', 'manual__2022-12-30T14:01:30.148908+00:00', '--job-id', '78', '--raw', '--subdir', 'DAGS_FOLDER/insert_new_rates.py', '--cfg-path', '/tmp/tmpsdi7i7xz', '--error-file', '/tmp/tmpxpwz7zki']
[2022-12-30 14:13:21,135] {standard_task_runner.py:80} INFO - Job 78: Subtask dag4_process_EOD_rates
[2022-12-30 14:13:21,178] {task_command.py:369} INFO - Running <TaskInstance: insert_new_rates.dag4_process_EOD_rates manual__2022-12-30T14:01:30.148908+00:00 [running]> on host 99c1092660ad
[2022-12-30 14:13:21,250] {taskinstance.py:1571} INFO - Exporting the following env vars:
AIRFLOW_CTX_DAG_OWNER=***
AIRFLOW_CTX_DAG_ID=insert_new_rates
AIRFLOW_CTX_TASK_ID=dag4_process_EOD_rates
AIRFLOW_CTX_EXECUTION_DATE=2022-12-30T14:01:30.148908+00:00
AIRFLOW_CTX_TRY_NUMBER=3
AIRFLOW_CTX_DAG_RUN_ID=manual__2022-12-30T14:01:30.148908+00:00
[2022-12-30 14:13:21,263] {taskinstance.py:1889} ERROR - Task failed with exception
Traceback (most recent call last):
  File "/home/airflow/.local/lib/python3.7/site-packages/airflow/decorators/base.py", line 179, in execute
    return_value = super().execute(context)
  File "/home/airflow/.local/lib/python3.7/site-packages/airflow/operators/python.py", line 171, in execute
    return_value = self.execute_callable()
  File "/home/airflow/.local/lib/python3.7/site-packages/airflow/operators/python.py", line 189, in execute_callable
    return self.python_callable(*self.op_args, **self.op_kwargs)
  File "/opt/airflow/dags/insert_new_rates.py", line 65, in dag4_process_EOD_rates
    process_EOD_rates(rates_df)
  File "/opt/airflow/dags/python/Helper.py", line 273, in process_EOD_rates
    new_df.to_csv(f'dags/processed_rates_{start_date}.csv')
  File "/home/airflow/.local/lib/python3.7/site-packages/pandas/core/generic.py", line 3482, in to_csv
    storage_options=storage_options,
  File "/home/airflow/.local/lib/python3.7/site-packages/pandas/io/formats/format.py", line 1105, in to_csv
    csv_formatter.save()
  File "/home/airflow/.local/lib/python3.7/site-packages/pandas/io/formats/csvs.py", line 243, in save
    storage_options=self.storage_options,
  File "/home/airflow/.local/lib/python3.7/site-packages/pandas/io/common.py", line 707, in get_handle
    newline="",
FileNotFoundError: [Errno 2] No such file or directory: 'dags/processed_rates_2022-03-04.csv'
[2022-12-30 14:13:21,280] {taskinstance.py:1400} INFO - Marking task as FAILED. dag_id=insert_new_rates, task_id=dag4_process_EOD_rates, execution_date=20221230T140130, start_date=20221230T141321, end_date=20221230T141321
[2022-12-30 14:13:21,291] {standard_task_runner.py:97} ERROR - Failed to execute job 78 for task dag4_process_EOD_rates ([Errno 2] No such file or directory: 'dags/processed_rates_2022-03-04.csv'; 8156)
[2022-12-30 14:13:21,307] {local_task_job.py:156} INFO - Task exited with return code 1
[2022-12-30 14:13:21,339] {local_task_job.py:273} INFO - 0 downstream tasks scheduled from follow-on schedule check
